<?xml version="1.0"?>
<robot name="cabinet_model">

  <link name="base"/>

  <link name="base_link">
    <visual>
      <geometry>
        <mesh filename="cabinet_body_rest.obj" scale="1 1 1"/>
      </geometry>
    </visual>
    <collision>
      <geometry>
        <mesh filename="cabinet_body_rest.obj" scale="1 1 1"/>
      </geometry>
    </collision>
  </link>
  
  <joint name="fixed_base_to_baselink" type="fixed">
    <parent link="base"/>
    <child link="base_link"/>
    <origin xyz="0 0 0" rpy="0 0 0"/>
  </joint>
  
  <link name="door_link">
    <visual>
      <origin xyz="" rpy="0 0 0"/>
      <geometry>
        <mesh filename="cabinet_door_part.obj" scale="1 1 1"/>
      </geometry>
    </visual>
    <collision>
      <origin xyz="" rpy="0 0 0"/>
      <geometry>
        <mesh filename="cabinet_door_part.obj" scale="1 1 1"/>
      </geometry>
    </collision>
  </link>

  <joint name="door_hinge" type="revolute">
    <parent link="base_link"/>
    <child link="door_link"/>
    <origin xyz="" rpy="0 0 0"/>
    <axis xyz="-0.9999148 0.012314251 0.0043329685"/>
    <limit lower="0.0" upper="1.6901768476313088"/>
  </joint>

</robot>
